<?xml version="1.0"?>
<robot name="frederico" xmlns:xacro="http://ros.org/wiki/xacro">

    <!-- Define robot constants -->
    <xacro:property name="base_width" value="0.31"/>
    <xacro:property name="base_length" value="0.42"/>
    <xacro:property name="base_height" value="0.18"/>

    <xacro:property name="wheel_radius" value="0.10"/>
    <xacro:property name="wheel_width" value="0.04"/>
    <xacro:property name="wheel_ygap" value="0.025"/>
    <xacro:property name="wheel_zoff" value="0.05"/>
    <xacro:property name="wheel_xoff" value="0.12"/>


    <!-- Robot Base -->
    <link name="base_link">
    <visual>
        <geometry>
        <box size="${base_length} ${base_width} ${base_height}"/>
        </geometry>
        <material name="Cyan">
        <color rgba="0 1.0 1.0 1.0"/>
        </material>
    </visual>
    </link>



    <!-- Robot Footprint -->
    <link name="base_footprint"/>

    <joint name="base_joint" type="fixed">
        <parent link="base_footprint"/>
        <child link="base_link"/>
        <origin xyz="0.0 0.0 ${(wheel_radius+wheel_zoff)}" rpy="0 0 0"/>
    </joint>


    <!-- Wheels -->
    <xacro:macro name="wheel" params="prefix x_reflect y_reflect">
        <link name="${prefix}_link">
        <visual>
            <origin xyz="0 0 0" rpy="${pi/2} 0 0"/>
            <geometry>
                <cylinder radius="${wheel_radius}" length="${wheel_width}"/>
            </geometry>
            <material name="Gray">
            <color rgba="0.5 0.5 0.5 1.0"/>
            </material>
        </visual>
        </link>

        <joint name="${prefix}_joint" type="continuous">
        <parent link="base_link"/>
        <child link="${prefix}_link"/>
        <origin xyz="${x_reflect*wheel_xoff} ${y_reflect*(base_width/2+wheel_ygap)} ${-wheel_zoff}" rpy="0 0 0"/>
        <axis xyz="0 1 0"/>
        </joint>
    </xacro:macro>

    <xacro:wheel prefix="wheel1" x_reflect="-1"    y_reflect="1" />
    <xacro:wheel prefix="wheel2" x_reflect="-1"    y_reflect="-1" />
    <xacro:wheel prefix="wheel3" x_reflect="1"     y_reflect="1"/>
    <xacro:wheel prefix="wheel4_link" x_reflect="1"     y_reflect="-1" />


    <!-- LIDAR  -->
    <link name="lidar_link">  
        <visual>
          <origin xyz="0 0 0" rpy="0 0 0"/>
          <geometry>
             <cylinder radius="0.0508" length="0.055"/>
          </geometry>
        </visual>
    </link>


    <joint name="lidar_joint" type="fixed">
        <parent link="base_link"/>
        <child link="lidar_link"/>
        <origin xyz="0 0 0.12" rpy="0 0 0"/>
    </joint>



    <!-- IMU -->
    <link name="imu_link">
        <visual>
          <geometry>
            <box size="0.1 0.1 0.1"/>
          </geometry>
        </visual>
    </link>

    <joint name="imu_joint" type="fixed">
        <parent link="base_link"/>
        <child link="imu_link"/>
        <origin xyz="0 0 0.01"/>
    </joint>


      
    <!-- Ultrasonics -->
    <link name="ultrasonic1_link">
        <visual>
          <geometry>
            <box size="0.01 0.01 0.01"/>
          </geometry>
        </visual>
    </link>

    <joint name="ultrasonic1_joint" type="fixed">
        <parent link="base_link"/>
        <child link="ultrasonic1_link"/>
        <origin xyz="0 0 0.01"/>
      </joint>

    

      <link name="ultrasonic2_link">
        <visual>
          <geometry>
            <box size="0.01 0.01 0.01"/>
          </geometry>
        </visual>
    </link>

    <joint name="ultrasonic2_joint" type="fixed">
        <parent link="base_link"/>
        <child link="ultrasonic2_link"/>
        <origin xyz="0 0 0.01"/>
      </joint>

    
    
      <link name="ultrasonic3_link">
        <visual>
          <geometry>
            <box size="0.01 0.01 0.01"/>
          </geometry>
        </visual>
    </link>

    <joint name="ultrasonic3_joint" type="fixed">
        <parent link="base_link"/>
        <child link="ultrasonic3_link"/>
        <origin xyz="0 0 0.01"/>
      </joint>

    







</robot>
